{"trial_id": "00", "hyperparameters": {"space": [{"class_name": "Int", "config": {"name": "num_layers", "default": null, "conditions": [], "min_value": 1, "max_value": 2, "step": 1, "sampling": "linear"}}, {"class_name": "Int", "config": {"name": "dense_units", "default": null, "conditions": [], "min_value": 8, "max_value": 80, "step": 8, "sampling": "linear"}}, {"class_name": "Float", "config": {"name": "l2_regularizer", "default": 0.0, "conditions": [], "min_value": 0.0, "max_value": 0.5, "step": 0.05, "sampling": "linear"}}, {"class_name": "Float", "config": {"name": "dropout", "default": 0.0, "conditions": [], "min_value": 0.0, "max_value": 0.8, "step": 0.2, "sampling": "linear"}}, {"class_name": "Int", "config": {"name": "lstm_units", "default": null, "conditions": [], "min_value": 8, "max_value": 80, "step": 8, "sampling": "linear"}}, {"class_name": "Float", "config": {"name": "lstm_kernel_regularizer", "default": 0.0, "conditions": [], "min_value": 0.0, "max_value": 0.5, "step": 0.05, "sampling": "linear"}}, {"class_name": "Float", "config": {"name": "lstm_recurrent_regularizer", "default": 0.0, "conditions": [], "min_value": 0.0, "max_value": 0.5, "step": 0.05, "sampling": "linear"}}, {"class_name": "Choice", "config": {"name": "lstm_activation", "default": "relu", "conditions": [], "values": ["relu", "swish", "sigmoid"], "ordered": false}}], "values": {"num_layers": 2, "dense_units": 8, "l2_regularizer": 0.2, "dropout": 0.2, "lstm_units": 72, "lstm_kernel_regularizer": 0.15000000000000002, "lstm_recurrent_regularizer": 0.25, "lstm_activation": "relu"}}, "metrics": {"metrics": {}}, "score": null, "best_step": 0, "status": "FAILED", "message": "Traceback (most recent call last):\n  File \"c:\\Users\\ryanm\\anaconda3\\Lib\\site-packages\\keras_tuner\\src\\engine\\base_tuner.py\", line 274, in _try_run_and_update_trial\n    self._run_and_update_trial(trial, *fit_args, **fit_kwargs)\n  File \"c:\\Users\\ryanm\\anaconda3\\Lib\\site-packages\\keras_tuner\\src\\engine\\base_tuner.py\", line 239, in _run_and_update_trial\n    results = self.run_trial(trial, *fit_args, **fit_kwargs)\n              ^^^^^^^^^^^^^^^^^^^^^^^^^^^^^^^^^^^^^^^^^^^^^^\n  File \"c:\\Users\\ryanm\\anaconda3\\Lib\\site-packages\\keras_tuner\\src\\engine\\tuner.py\", line 314, in run_trial\n    obj_value = self._build_and_fit_model(trial, *args, **copied_kwargs)\n                ^^^^^^^^^^^^^^^^^^^^^^^^^^^^^^^^^^^^^^^^^^^^^^^^^^^^^^^^\n  File \"c:\\Users\\ryanm\\anaconda3\\Lib\\site-packages\\keras_tuner\\src\\engine\\tuner.py\", line 233, in _build_and_fit_model\n    results = self.hypermodel.fit(hp, model, *args, **kwargs)\n              ^^^^^^^^^^^^^^^^^^^^^^^^^^^^^^^^^^^^^^^^^^^^^^^\n  File \"c:\\Users\\ryanm\\anaconda3\\Lib\\site-packages\\keras_tuner\\src\\engine\\hypermodel.py\", line 149, in fit\n    return model.fit(*args, **kwargs)\n           ^^^^^^^^^^^^^^^^^^^^^^^^^^\n  File \"c:\\Users\\ryanm\\anaconda3\\Lib\\site-packages\\keras\\src\\utils\\traceback_utils.py\", line 122, in error_handler\n    raise e.with_traceback(filtered_tb) from None\n  File \"c:\\Users\\ryanm\\anaconda3\\Lib\\site-packages\\keras\\src\\models\\functional.py\", line 288, in _adjust_input_rank\n    raise ValueError(\nValueError: Exception encountered when calling Sequential.call().\n\n\u001b[1mInvalid input shape for input Tensor(\"data:0\", shape=(None, 6), dtype=float32). Expected shape (None, None, 6), but input has incompatible shape (None, 6)\u001b[0m\n\nArguments received by Sequential.call():\n  \u2022 inputs=tf.Tensor(shape=(None, 6), dtype=float32)\n  \u2022 training=True\n  \u2022 mask=None\n"}